[2024-09-16T00:03:30.601+0000] {local_task_job_runner.py:123} INFO - ::group::Pre task execution logs
[2024-09-16T00:03:30.767+0000] {taskinstance.py:2612} INFO - Dependencies all met for dep_context=non-requeueable deps ti=<TaskInstance: etl-cocktails.creacion-data-frame scheduled__2024-08-27T00:00:00+00:00 [queued]>
[2024-09-16T00:03:30.775+0000] {taskinstance.py:2612} INFO - Dependencies all met for dep_context=requeueable deps ti=<TaskInstance: etl-cocktails.creacion-data-frame scheduled__2024-08-27T00:00:00+00:00 [queued]>
[2024-09-16T00:03:30.776+0000] {taskinstance.py:2865} INFO - Starting attempt 3 of 4
[2024-09-16T00:03:30.790+0000] {taskinstance.py:2888} INFO - Executing <Task(PythonOperator): creacion-data-frame> on 2024-08-27 00:00:00+00:00
[2024-09-16T00:03:30.797+0000] {warnings.py:112} WARNING - /home/***/.local/lib/python3.12/site-packages/***/task/task_runner/standard_task_runner.py:70: DeprecationWarning: This process (pid=124) is multi-threaded, use of fork() may lead to deadlocks in the child.
  pid = os.fork()

[2024-09-16T00:03:30.800+0000] {standard_task_runner.py:72} INFO - Started process 128 to run task
[2024-09-16T00:03:30.800+0000] {standard_task_runner.py:104} INFO - Running: ['***', 'tasks', 'run', 'etl-cocktails', 'creacion-data-frame', 'scheduled__2024-08-27T00:00:00+00:00', '--job-id', '164', '--raw', '--subdir', 'DAGS_FOLDER/dag_etl_cocktails.py', '--cfg-path', '/tmp/tmpqexc7z0i']
[2024-09-16T00:03:30.803+0000] {standard_task_runner.py:105} INFO - Job 164: Subtask creacion-data-frame
[2024-09-16T00:03:30.859+0000] {task_command.py:467} INFO - Running <TaskInstance: etl-cocktails.creacion-data-frame scheduled__2024-08-27T00:00:00+00:00 [running]> on host 84e286ef6159
[2024-09-16T00:03:30.949+0000] {taskinstance.py:3131} INFO - Exporting env vars: AIRFLOW_CTX_DAG_OWNER='juansaobento' AIRFLOW_CTX_DAG_ID='etl-cocktails' AIRFLOW_CTX_TASK_ID='creacion-data-frame' AIRFLOW_CTX_EXECUTION_DATE='2024-08-27T00:00:00+00:00' AIRFLOW_CTX_TRY_NUMBER='3' AIRFLOW_CTX_DAG_RUN_ID='scheduled__2024-08-27T00:00:00+00:00'
[2024-09-16T00:03:30.951+0000] {taskinstance.py:731} INFO - ::endgroup::
[2024-09-16T00:03:30.965+0000] {taskinstance.py:3310} ERROR - Task failed with exception
Traceback (most recent call last):
  File "/home/airflow/.local/lib/python3.12/site-packages/airflow/models/taskinstance.py", line 767, in _execute_task
    result = _execute_callable(context=context, **execute_callable_kwargs)
             ^^^^^^^^^^^^^^^^^^^^^^^^^^^^^^^^^^^^^^^^^^^^^^^^^^^^^^^^^^^^^
  File "/home/airflow/.local/lib/python3.12/site-packages/airflow/models/taskinstance.py", line 733, in _execute_callable
    return ExecutionCallableRunner(
           ^^^^^^^^^^^^^^^^^^^^^^^^
  File "/home/airflow/.local/lib/python3.12/site-packages/airflow/utils/operator_helpers.py", line 252, in run
    return self.func(*args, **kwargs)
           ^^^^^^^^^^^^^^^^^^^^^^^^^^
  File "/home/airflow/.local/lib/python3.12/site-packages/airflow/models/baseoperator.py", line 406, in wrapper
    return func(self, *args, **kwargs)
           ^^^^^^^^^^^^^^^^^^^^^^^^^^^
  File "/home/airflow/.local/lib/python3.12/site-packages/airflow/operators/python.py", line 238, in execute
    return_value = self.execute_callable()
                   ^^^^^^^^^^^^^^^^^^^^^^^
  File "/home/airflow/.local/lib/python3.12/site-packages/airflow/operators/python.py", line 256, in execute_callable
    return runner.run(*self.op_args, **self.op_kwargs)
           ^^^^^^^^^^^^^^^^^^^^^^^^^^^^^^^^^^^^^^^^^^^
  File "/home/airflow/.local/lib/python3.12/site-packages/airflow/utils/operator_helpers.py", line 252, in run
    return self.func(*args, **kwargs)
           ^^^^^^^^^^^^^^^^^^^^^^^^^^
  File "/opt/airflow/dags/build_dataframe.py", line 11, in creacion_df
    datalist= obtencion_datos()
              ^^^^^^^^^^^^^^^^^
TypeError: 'module' object is not callable
[2024-09-16T00:03:31.004+0000] {taskinstance.py:1225} INFO - Marking task as UP_FOR_RETRY. dag_id=etl-cocktails, task_id=creacion-data-frame, run_id=scheduled__2024-08-27T00:00:00+00:00, execution_date=20240827T000000, start_date=20240916T000330, end_date=20240916T000330
[2024-09-16T00:03:31.065+0000] {taskinstance.py:340} INFO - ::group::Post task execution logs
[2024-09-16T00:03:31.066+0000] {standard_task_runner.py:124} ERROR - Failed to execute job 164 for task creacion-data-frame ('module' object is not callable; 128)
Traceback (most recent call last):
  File "/home/airflow/.local/lib/python3.12/site-packages/airflow/task/task_runner/standard_task_runner.py", line 117, in _start_by_fork
    ret = args.func(args, dag=self.dag)
          ^^^^^^^^^^^^^^^^^^^^^^^^^^^^^
  File "/home/airflow/.local/lib/python3.12/site-packages/airflow/cli/cli_config.py", line 49, in command
    return func(*args, **kwargs)
           ^^^^^^^^^^^^^^^^^^^^^
  File "/home/airflow/.local/lib/python3.12/site-packages/airflow/utils/cli.py", line 115, in wrapper
    return f(*args, **kwargs)
           ^^^^^^^^^^^^^^^^^^
  File "/home/airflow/.local/lib/python3.12/site-packages/airflow/cli/commands/task_command.py", line 483, in task_run
    task_return_code = _run_task_by_selected_method(args, _dag, ti)
                       ^^^^^^^^^^^^^^^^^^^^^^^^^^^^^^^^^^^^^^^^^^^^
  File "/home/airflow/.local/lib/python3.12/site-packages/airflow/cli/commands/task_command.py", line 256, in _run_task_by_selected_method
    return _run_raw_task(args, ti)
           ^^^^^^^^^^^^^^^^^^^^^^^
  File "/home/airflow/.local/lib/python3.12/site-packages/airflow/cli/commands/task_command.py", line 341, in _run_raw_task
    return ti._run_raw_task(
           ^^^^^^^^^^^^^^^^^
  File "/home/airflow/.local/lib/python3.12/site-packages/airflow/utils/session.py", line 97, in wrapper
    return func(*args, session=session, **kwargs)
           ^^^^^^^^^^^^^^^^^^^^^^^^^^^^^^^^^^^^^^
  File "/home/airflow/.local/lib/python3.12/site-packages/airflow/models/taskinstance.py", line 3004, in _run_raw_task
    return _run_raw_task(
           ^^^^^^^^^^^^^^
  File "/home/airflow/.local/lib/python3.12/site-packages/airflow/models/taskinstance.py", line 273, in _run_raw_task
    TaskInstance._execute_task_with_callbacks(
  File "/home/airflow/.local/lib/python3.12/site-packages/airflow/models/taskinstance.py", line 3158, in _execute_task_with_callbacks
    result = self._execute_task(context, task_orig)
             ^^^^^^^^^^^^^^^^^^^^^^^^^^^^^^^^^^^^^^
  File "/home/airflow/.local/lib/python3.12/site-packages/airflow/models/taskinstance.py", line 3182, in _execute_task
    return _execute_task(self, context, task_orig)
           ^^^^^^^^^^^^^^^^^^^^^^^^^^^^^^^^^^^^^^^
  File "/home/airflow/.local/lib/python3.12/site-packages/airflow/models/taskinstance.py", line 767, in _execute_task
    result = _execute_callable(context=context, **execute_callable_kwargs)
             ^^^^^^^^^^^^^^^^^^^^^^^^^^^^^^^^^^^^^^^^^^^^^^^^^^^^^^^^^^^^^
  File "/home/airflow/.local/lib/python3.12/site-packages/airflow/models/taskinstance.py", line 733, in _execute_callable
    return ExecutionCallableRunner(
           ^^^^^^^^^^^^^^^^^^^^^^^^
  File "/home/airflow/.local/lib/python3.12/site-packages/airflow/utils/operator_helpers.py", line 252, in run
    return self.func(*args, **kwargs)
           ^^^^^^^^^^^^^^^^^^^^^^^^^^
  File "/home/airflow/.local/lib/python3.12/site-packages/airflow/models/baseoperator.py", line 406, in wrapper
    return func(self, *args, **kwargs)
           ^^^^^^^^^^^^^^^^^^^^^^^^^^^
  File "/home/airflow/.local/lib/python3.12/site-packages/airflow/operators/python.py", line 238, in execute
    return_value = self.execute_callable()
                   ^^^^^^^^^^^^^^^^^^^^^^^
  File "/home/airflow/.local/lib/python3.12/site-packages/airflow/operators/python.py", line 256, in execute_callable
    return runner.run(*self.op_args, **self.op_kwargs)
           ^^^^^^^^^^^^^^^^^^^^^^^^^^^^^^^^^^^^^^^^^^^
  File "/home/airflow/.local/lib/python3.12/site-packages/airflow/utils/operator_helpers.py", line 252, in run
    return self.func(*args, **kwargs)
           ^^^^^^^^^^^^^^^^^^^^^^^^^^
  File "/opt/airflow/dags/build_dataframe.py", line 11, in creacion_df
    datalist= obtencion_datos()
              ^^^^^^^^^^^^^^^^^
TypeError: 'module' object is not callable
[2024-09-16T00:03:31.143+0000] {local_task_job_runner.py:266} INFO - Task exited with return code 1
[2024-09-16T00:03:31.193+0000] {taskinstance.py:3900} INFO - 0 downstream tasks scheduled from follow-on schedule check
[2024-09-16T00:03:31.196+0000] {local_task_job_runner.py:245} INFO - ::endgroup::
